Workbook
Name Slicer_Metric: #N/A
Name Slicer_Metric1: #N/A

Sheet Cover
E16: SOCIAL MEDIA ANALYTICS DASHBOARD
G17: SEASON: 2026/27
E19: Prepared for : XXXXXXXX
E20: Prepared by : Raj Singh
I26: Version 1.2 (July 2026)
I27: Last Updated: 31/07/2026
D31: © 2026 Raj Singh. This dashboard and its design may not be reproduced, distributed or modified without permission.

Sheet User Guide
A1: Raj Singh (2026)
V3: Dashboard Version | W3: v1.0
V4: Prepared for: | W4: XXXXX
V5: Prepared by: | W5: Raj Singh
C41: APPENDIX
H44: * Manipulated Data
C45: a) | D45: Reading the simplified charts:
D46: Select the 'Processed Data' sheet from the panel below
D47: Find the corresponding month highlighted in yellow at the top
D48: Each media channel is listed down the side
D49: There you can see the monthly change on the previous month
D50: Green indicates an increase, Red indicates a decrease and the value is the raw amount
H56: ** Dynamic Graphs
C57: a) | D57: Understanding the tab:
D58: Select the 'Dynamic Graphs' sheet from the bottom pannel
D59: Here there will be a few tables: the green table is raw data, blue is filtered
D60: On the right are 3 charts that will change based on the next steps
C62: b) | D62: Preparing the Data for a graph:
D63: Firstly, a graph will only be correctly generated if the data in step 1 ("Data") is correct and up to date
D64: Once the "Data" tab is complete - make sure you are working in the "Dynamic Graphs" sheet
D65: Right click anywhere in the GREEN table, then press "Refresh" - this is to ensure the data is up to date
D66: IF YOU CAN'T DO THAT - click normally anywhere in the GREEN table --> "Table Design" at the top --> Refresh
D67: Then, Right click anywhere in the BLUE table, then press "Refresh" - this ensures the blue matches the green
C69: c) | D69: Making the graphs:
D70: Now after steps 3.1 and 3.2, the graphs can be made easily
D71: There is a 'slicer' which looks like a TV channel guide inbetween the BLUE table and the bar chart
D72: Scroll down and click whichever metric you would like to display
D73: The 3 charts should then update accordingly
C75: d) | D75: Changing the graph appearance:
D76: TITLE/ AXIS LABEL - click once where it says "CHANGE TITLE NAME" or "Axis Title" and then drag your cursor so the text is selected, then type in the title you want
D77: COLOUR/ BARS - click once on any bar or line in the chart --> "Design" at the top --> play around with the colour changes
D78: ADDED EXTRAS - Click anywhere on the white box of a chart --> at the top right there will be a green PLUS and a blue PAINTBRUSH --> these features can add extras that may be useful

Sheet Dashboard
E2: Social Media Performance Dashboard | V2: Last Updated | W2: Current Month | AU2: FOR RAJ USE - LINKED/ CODED CELLS | BA2: Helper | BB2: {=_xlfn.SWITCH(M5, "X","X - ", "TikTok","TT - ", "Instagram","IG - ", "Threads","THREADS - ", "Facebook","FB - ", "LinkedIn","LINKEDIN - ", "")} -> X - | BJ2: Metric | BK2: Card Title | BL2: Value | BM2: Display Val | BN2: Growth | BO2: Growth Display | BQ2: Platform | BR2: Primary Chart Metric | BU2: Chart 1 | BX2: Chart 2 | CB2: Chart 3 (BR) | CJ2: Bottom Left
E3: Season 2026/27 | V3: 46204 | W3: =TODAY() -> 46262 | BB3: {=_xlfn._xlws.FILTER(MensData[Metric],LEFT(MensData[Metric],LEN($BB$2))=$BB$2,"")} -> X - Followers | BJ3: {=IFERROR(INDEX(_xlfn.ANCHORARRAY($BB$3),ROWS($BF$2:BF2)),"")} -> X - Followers | BK3: =IF(BJ3="","",TRIM(_xlfn.TEXTAFTER(BJ3,"-"))) -> Followers | BL3: {=IF(BJ3="","",INDEX('Data Entry'!$D$5:$Q$34,_xlfn.XMATCH(BJ3,'Data Entry'!$C$5:$C$34,0),_xlfn.XMATCH($N$5,'Data Entry'!$D$4:$Q$4,0)))} -> 242000 | BM3: =IF(BL3="","", IF(ISNUMBER(SEARCH("Engagement rate",BK3)), TEXT(BL3,"0.0%"), TEXT(BL3,"#,##0"))) -> 242,000 | BN3: {=IF(BJ3="","",INDEX('Data Entry'!$AA$5:$AN$34,_xlfn.XMATCH(BJ3,'Data Entry'!$Z$5:$Z$34,0),_xlfn.XMATCH($N$5,'Data Entry'!$AA$4:$AN$4,0)))} -> 0.0029009532 | BO3: =IF(BN3="","",IF(BN3>0,"▲ "&TEXT(BN3,"0.00%"),IF(BN3<0,"▼ "&TEXT(ABS(BN3),"0.00%"),"▬ 0.00%"))) -> ▲ 0.29% | BQ3: X | BR3: ='Data Entry'!C6 -> X - Impressions | BS3: =_xlfn.XLOOKUP(C24,$BQ$3:$BQ$8,$BR$3:$BR$8) -> THREADS - Views | BU3: Month | BV3: Value | BX3: Month | BY3: Value | BZ3: =TRIM(_xlfn.TEXTAFTER($V$24,)) & " by Month" -> X - Profile visits by Month | CB3: Month | CC3: Value | CD3: =TRIM(_xlfn.TEXTAFTER($V$34,))&" Insights" -> X - Video Views Insights | CF3: =$U$34&" - "&TRIM(_xlfn.TEXTAFTER(CD3,"-")) -> X - Video Views Insights | CJ3: Highest KPI: | CK3: {=INDEX($CM$23:$CM$40,_xlfn.XMATCH(MAX($CN$23:$CN$40),$CN$23:$CN$40))} -> Views | CL3: =MAX($CN$23:$CN$40) -> 486000 | CN3: =CK3&" ("&TEXT(CL3,"#,##0")&")" -> Views (486,000) | CQ3: =$C$34&"-"&" Executive Summary"&" ("&N5&")" -> TikTok- Executive Summary (Dec-26)
M4: Platform ▼ | N4: Month ▼ | BB4: X - Impressions | BJ4: {=IFERROR(INDEX(_xlfn.ANCHORARRAY($BB$3),ROWS($BF$2:BF3)),"")} -> X - Impressions | BK4: =IF(BJ4="","",TRIM(_xlfn.TEXTAFTER(BJ4,"-"))) -> Impressions | BL4: {=IF(BJ4="","",INDEX('Data Entry'!$D$5:$Q$34,_xlfn.XMATCH(BJ4,'Data Entry'!$C$5:$C$34,0),_xlfn.XMATCH($N$5,'Data Entry'!$D$4:$Q$4,0)))} -> 3900000 | BM4: =IF(BL4="","", IF(ISNUMBER(SEARCH("Engagement rate",BK4)), TEXT(BL4,"0.0%"), TEXT(BL4,"#,##0"))) -> 3,900,000 | BN4: {=IF(BJ4="","",INDEX('Data Entry'!$AA$5:$AN$34,_xlfn.XMATCH(BJ4,'Data Entry'!$Z$5:$Z$34,0),_xlfn.XMATCH($N$5,'Data Entry'!$AA$4:$AN$4,0)))} -> -0.11363636 | BO4: =IF(BN4="","",IF(BN4>0,"▲ "&TEXT(BN4,"0.00%"),IF(BN4<0,"▼ "&TEXT(ABS(BN4),"0.00%"),"▬ 0.00%"))) -> ▼ 11.36% | BQ4: TikTok | BR4: ='Data Entry'!C16 -> TT - Views | BS4: =$C$24&" - "&TRIM(_xlfn.TEXTAFTER(BS3,"-"))&" Trend" -> Threads - Views Trend | BU4: =MensData[[#Headers],[May-26]] -> May-26 | BV4: {=INDEX('Data Entry'!$D$5:$Q$34, _xlfn.XMATCH($BS$3,'Data Entry'!$C$5:$C$34,0), _xlfn.XMATCH(BU4,'Data Entry'!$D$4:$Q$4,0))} -> 17600 | BX4: =BU4 -> May-26 | BY4: {=INDEX('Data Entry'!$D$5:$Q$34, _xlfn.XMATCH($V$24,'Data Entry'!$C$5:$C$34,0), _xlfn.XMATCH(BX4,'Data Entry'!$D$4:$Q$4,0))} -> 29800 | CB4: =BX4 -> May-26 | CC4: {=INDEX('Data Entry'!$D$5:$Q$34, _xlfn.XMATCH($V$34,'Data Entry'!$C$5:$C$34,0), _xlfn.XMATCH(CB4,'Data Entry'!$D$4:$Q$4,0))} -> 342600 | CF4: Peak Month: | CG4: =_xlfn.XLOOKUP(MAX(CC4:CC17),CC4:CC17,CB4:CB17) -> Jul-26 | CJ4: Largest Increase: | CK4: {=INDEX($CM$23:$CM$40,_xlfn.XMATCH(MAX($CO$23:$CO$40),$CO$23:$CO$40))} -> New Viewers | CL4: =MAX($CO$23:$CO$40) -> 3.3809524 | CN4: =CK4&" (+"&TEXT(CL4,"0.0%")&")" -> New Viewers (+338.1%)
M5: X | N5: Dec-26 | BB5: X - Engagement rate | BJ5: {=IFERROR(INDEX(_xlfn.ANCHORARRAY($BB$3),ROWS($BF$2:BF4)),"")} -> X - Engagement rate | BK5: =IF(BJ5="","",TRIM(_xlfn.TEXTAFTER(BJ5,"-"))) -> Engagement rate | BL5: {=IF(BJ5="","",INDEX('Data Entry'!$D$5:$Q$34,_xlfn.XMATCH(BJ5,'Data Entry'!$C$5:$C$34,0),_xlfn.XMATCH($N$5,'Data Entry'!$D$4:$Q$4,0)))} -> 0.046 | BM5: =IF(BL5="","", IF(ISNUMBER(SEARCH("Engagement rate",BK5)), TEXT(BL5,"0.0%"), TEXT(BL5,"#,##0"))) -> 4.6% | BN5: {=IF(BJ5="","",INDEX('Data Entry'!$AA$5:$AN$34,_xlfn.XMATCH(BJ5,'Data Entry'!$Z$5:$Z$34,0),_xlfn.XMATCH($N$5,'Data Entry'!$AA$4:$AN$4,0)))} -> 0.095238095 | BO5: =IF(BN5="","",IF(BN5>0,"▲ "&TEXT(BN5,"0.00%"),IF(BN5<0,"▼ "&TEXT(ABS(BN5),"0.00%"),"▬ 0.00%"))) -> ▲ 9.52% | BQ5: Instagram | BR5: ='Data Entry'!C22 -> IG - Reel and Post Views | BU5: =MensData[[#Headers],[Jun-26]] -> Jun-26 | BV5: {=INDEX('Data Entry'!$D$5:$Q$34, _xlfn.XMATCH($BS$3,'Data Entry'!$C$5:$C$34,0), _xlfn.XMATCH(BU5,'Data Entry'!$D$4:$Q$4,0))} -> 32400 | BX5: =BU5 -> Jun-26 | BY5: {=INDEX('Data Entry'!$D$5:$Q$34, _xlfn.XMATCH($V$24,'Data Entry'!$C$5:$C$34,0), _xlfn.XMATCH(BX5,'Data Entry'!$D$4:$Q$4,0))} -> 89200 | CB5: =BX5 -> Jun-26 | CC5: {=INDEX('Data Entry'!$D$5:$Q$34, _xlfn.XMATCH($V$34,'Data Entry'!$C$5:$C$34,0), _xlfn.XMATCH(CB5,'Data Entry'!$D$4:$Q$4,0))} -> 493400 | CF5: Peak Value: | CG5: =MAX(CC4:CC17) -> 698800 | CJ5: Largest Decrease: | CK5: {=INDEX($CM$23:$CM$40,_xlfn.XMATCH(MIN($CO$23:$CO$40),$CO$23:$CO$40))} -> Comments | CL5: =MIN($CO$23:$CO$40) -> 0.13513514 | CN5: =CK5&" ("&TEXT(CL5,"0.0%")&")" -> Comments (13.5%)
BB6: X - Engagements | BJ6: {=IFERROR(INDEX(_xlfn.ANCHORARRAY($BB$3),ROWS($BF$2:BF5)),"")} -> X - Engagements | BK6: =IF(BJ6="","",TRIM(_xlfn.TEXTAFTER(BJ6,"-"))) -> Engagements | BL6: {=IF(BJ6="","",INDEX('Data Entry'!$D$5:$Q$34,_xlfn.XMATCH(BJ6,'Data Entry'!$C$5:$C$34,0),_xlfn.XMATCH($N$5,'Data Entry'!$D$4:$Q$4,0)))} -> 183400 | BM6: =IF(BL6="","", IF(ISNUMBER(SEARCH("Engagement rate",BK6)), TEXT(BL6,"0.0%"), TEXT(BL6,"#,##0"))) -> 183,400 | BN6: {=IF(BJ6="","",INDEX('Data Entry'!$AA$5:$AN$34,_xlfn.XMATCH(BJ6,'Data Entry'!$Z$5:$Z$34,0),_xlfn.XMATCH($N$5,'Data Entry'!$AA$4:$AN$4,0)))} -> -0.033210332 | BO6: =IF(BN6="","",IF(BN6>0,"▲ "&TEXT(BN6,"0.00%"),IF(BN6<0,"▼ "&TEXT(ABS(BN6),"0.00%"),"▬ 0.00%"))) -> ▼ 3.32% | BQ6: Threads | BR6: ='Data Entry'!C26 -> THREADS - Views | BU6: =MensData[[#Headers],[Jul-26]] -> Jul-26 | BV6: {=INDEX('Data Entry'!$D$5:$Q$34, _xlfn.XMATCH($BS$3,'Data Entry'!$C$5:$C$34,0), _xlfn.XMATCH(BU6,'Data Entry'!$D$4:$Q$4,0))} -> 17000 | BX6: =BU6 -> Jul-26 | BY6: {=INDEX('Data Entry'!$D$5:$Q$34, _xlfn.XMATCH($V$24,'Data Entry'!$C$5:$C$34,0), _xlfn.XMATCH(BX6,'Data Entry'!$D$4:$Q$4,0))} -> 100600 | CB6: =BX6 -> Jul-26 | CC6: {=INDEX('Data Entry'!$D$5:$Q$34, _xlfn.XMATCH($V$34,'Data Entry'!$C$5:$C$34,0), _xlfn.XMATCH(CB6,'Data Entry'!$D$4:$Q$4,0))} -> 698800 | CF6: Lowest Month: | CG6: =_xlfn.XLOOKUP(_xlfn.MINIFS(CC4:CC17,CC4:CC17,">0"),CC4:CC17,CB4:CB17) -> Nov-26 | CJ6: KPIs Improving: | CK6: =COUNTIF($CO$23:$CO$39,">0")&" / "&COUNTIF($CL$23:$CL$39,"?*") -> 6 / 6
BB7: X - Profile visits | BJ7: {=IFERROR(INDEX(_xlfn.ANCHORARRAY($BB$3),ROWS($BF$2:BF6)),"")} -> X - Profile visits | BK7: =IF(BJ7="","",TRIM(_xlfn.TEXTAFTER(BJ7,"-"))) -> Profile visits | BL7: {=IF(BJ7="","",INDEX('Data Entry'!$D$5:$Q$34,_xlfn.XMATCH(BJ7,'Data Entry'!$C$5:$C$34,0),_xlfn.XMATCH($N$5,'Data Entry'!$D$4:$Q$4,0)))} -> 33900 | BM7: =IF(BL7="","", IF(ISNUMBER(SEARCH("Engagement rate",BK7)), TEXT(BL7,"0.0%"), TEXT(BL7,"#,##0"))) -> 33,900 | BN7: {=IF(BJ7="","",INDEX('Data Entry'!$AA$5:$AN$34,_xlfn.XMATCH(BJ7,'Data Entry'!$Z$5:$Z$34,0),_xlfn.XMATCH($N$5,'Data Entry'!$AA$4:$AN$4,0)))} -> -0.1285347 | BO7: =IF(BN7="","",IF(BN7>0,"▲ "&TEXT(BN7,"0.00%"),IF(BN7<0,"▼ "&TEXT(ABS(BN7),"0.00%"),"▬ 0.00%"))) -> ▼ 12.85% | BQ7: Facebook | BR7: ='Data Entry'!C28 -> FB - Views | BU7: =MensData[[#Headers],[Aug-26]] -> Aug-26 | BV7: {=INDEX('Data Entry'!$D$5:$Q$34, _xlfn.XMATCH($BS$3,'Data Entry'!$C$5:$C$34,0), _xlfn.XMATCH(BU7,'Data Entry'!$D$4:$Q$4,0))} -> 22400 | BX7: =BU7 -> Aug-26 | BY7: {=INDEX('Data Entry'!$D$5:$Q$34, _xlfn.XMATCH($V$24,'Data Entry'!$C$5:$C$34,0), _xlfn.XMATCH(BX7,'Data Entry'!$D$4:$Q$4,0))} -> 71900 | CB7: =BX7 -> Aug-26 | CC7: {=INDEX('Data Entry'!$D$5:$Q$34, _xlfn.XMATCH($V$34,'Data Entry'!$C$5:$C$34,0), _xlfn.XMATCH(CB7,'Data Entry'!$D$4:$Q$4,0))} -> 613900 | CF7: Lowest Value: | CG7: =_xlfn.MINIFS(CC4:CC17,CC4:CC17,">0") -> 207700 | CJ7: KPIs Declining: | CK7: =COUNTIF($CO$23:$CO$39,"<0")&" / "&COUNTIF($CL$23:$CL$39,"?*") -> 0 / 6
BB8: X - Replies | BJ8: {=IFERROR(INDEX(_xlfn.ANCHORARRAY($BB$3),ROWS($BF$2:BF7)),"")} -> X - Replies | BK8: =IF(BJ8="","",TRIM(_xlfn.TEXTAFTER(BJ8,"-"))) -> Replies | BL8: {=IF(BJ8="","",INDEX('Data Entry'!$D$5:$Q$34,_xlfn.XMATCH(BJ8,'Data Entry'!$C$5:$C$34,0),_xlfn.XMATCH($N$5,'Data Entry'!$D$4:$Q$4,0)))} -> 3900 | BM8: =IF(BL8="","", IF(ISNUMBER(SEARCH("Engagement rate",BK8)), TEXT(BL8,"0.0%"), TEXT(BL8,"#,##0"))) -> 3,900 | BN8: {=IF(BJ8="","",INDEX('Data Entry'!$AA$5:$AN$34,_xlfn.XMATCH(BJ8,'Data Entry'!$Z$5:$Z$34,0),_xlfn.XMATCH($N$5,'Data Entry'!$AA$4:$AN$4,0)))} -> 0.21875 | BO8: =IF(BN8="","",IF(BN8>0,"▲ "&TEXT(BN8,"0.00%"),IF(BN8<0,"▼ "&TEXT(ABS(BN8),"0.00%"),"▬ 0.00%"))) -> ▲ 21.88% | BQ8: Linkedin | BR8: ='Data Entry'!C32 -> LINKEDIN - Impressions | BU8: =MensData[[#Headers],[Sep-26]] -> Sep-26 | BV8: {=INDEX('Data Entry'!$D$5:$Q$34, _xlfn.XMATCH($BS$3,'Data Entry'!$C$5:$C$34,0), _xlfn.XMATCH(BU8,'Data Entry'!$D$4:$Q$4,0))} -> 15600 | BX8: =BU8 -> Sep-26 | BY8: {=INDEX('Data Entry'!$D$5:$Q$34, _xlfn.XMATCH($V$24,'Data Entry'!$C$5:$C$34,0), _xlfn.XMATCH(BX8,'Data Entry'!$D$4:$Q$4,0))} -> 68100 | CB8: =BX8 -> Sep-26 | CC8: {=INDEX('Data Entry'!$D$5:$Q$34, _xlfn.XMATCH($V$34,'Data Entry'!$C$5:$C$34,0), _xlfn.XMATCH(CB8,'Data Entry'!$D$4:$Q$4,0))} -> 322100 | CF8: Monthly Average: | CG8: =AVERAGEIF(CC4:CC17,"<>0") -> 435595.86
BB9: X - Likes | BJ9: {=IFERROR(INDEX(_xlfn.ANCHORARRAY($BB$3),ROWS($BF$2:BF8)),"")} -> X - Likes | BK9: =IF(BJ9="","",TRIM(_xlfn.TEXTAFTER(BJ9,"-"))) -> Likes | BL9: {=IF(BJ9="","",INDEX('Data Entry'!$D$5:$Q$34,_xlfn.XMATCH(BJ9,'Data Entry'!$C$5:$C$34,0),_xlfn.XMATCH($N$5,'Data Entry'!$D$4:$Q$4,0)))} -> 26300 | BM9: =IF(BL9="","", IF(ISNUMBER(SEARCH("Engagement rate",BK9)), TEXT(BL9,"0.0%"), TEXT(BL9,"#,##0"))) -> 26,300 | BN9: {=IF(BJ9="","",INDEX('Data Entry'!$AA$5:$AN$34,_xlfn.XMATCH(BJ9,'Data Entry'!$Z$5:$Z$34,0),_xlfn.XMATCH($N$5,'Data Entry'!$AA$4:$AN$4,0)))} -> 0.16888889 | BO9: =IF(BN9="","",IF(BN9>0,"▲ "&TEXT(BN9,"0.00%"),IF(BN9<0,"▼ "&TEXT(ABS(BN9),"0.00%"),"▬ 0.00%"))) -> ▲ 16.89% | BU9: =MensData[[#Headers],[Oct-26]] -> Oct-26 | BV9: {=INDEX('Data Entry'!$D$5:$Q$34, _xlfn.XMATCH($BS$3,'Data Entry'!$C$5:$C$34,0), _xlfn.XMATCH(BU9,'Data Entry'!$D$4:$Q$4,0))} -> 5199 | BX9: =BU9 -> Oct-26 | BY9: {=INDEX('Data Entry'!$D$5:$Q$34, _xlfn.XMATCH($V$24,'Data Entry'!$C$5:$C$34,0), _xlfn.XMATCH(BX9,'Data Entry'!$D$4:$Q$4,0))} -> 34300 | CB9: =BX9 -> Oct-26 | CC9: {=INDEX('Data Entry'!$D$5:$Q$34, _xlfn.XMATCH($V$34,'Data Entry'!$C$5:$C$34,0), _xlfn.XMATCH(CB9,'Data Entry'!$D$4:$Q$4,0))} -> 233500 | CF9: Selected Month: | CG9: =$N$5 -> Dec-26
BB10: X - Reposts | BJ10: {=IFERROR(INDEX(_xlfn.ANCHORARRAY($BB$3),ROWS($BF$2:BF9)),"")} -> X - Reposts | BK10: =IF(BJ10="","",TRIM(_xlfn.TEXTAFTER(BJ10,"-"))) -> Reposts | BL10: {=IF(BJ10="","",INDEX('Data Entry'!$D$5:$Q$34,_xlfn.XMATCH(BJ10,'Data Entry'!$C$5:$C$34,0),_xlfn.XMATCH($N$5,'Data Entry'!$D$4:$Q$4,0)))} -> 1300 | BM10: =IF(BL10="","", IF(ISNUMBER(SEARCH("Engagement rate",BK10)), TEXT(BL10,"0.0%"), TEXT(BL10,"#,##0"))) -> 1,300 | BN10: {=IF(BJ10="","",INDEX('Data Entry'!$AA$5:$AN$34,_xlfn.XMATCH(BJ10,'Data Entry'!$Z$5:$Z$34,0),_xlfn.XMATCH($N$5,'Data Entry'!$AA$4:$AN$4,0)))} -> -0.071428571 | BO10: =IF(BN10="","",IF(BN10>0,"▲ "&TEXT(BN10,"0.00%"),IF(BN10<0,"▼ "&TEXT(ABS(BN10),"0.00%"),"▬ 0.00%"))) -> ▼ 7.14% | BU10: =MensData[[#Headers],[Nov-26]] -> Nov-26 | BV10: {=INDEX('Data Entry'!$D$5:$Q$34, _xlfn.XMATCH($BS$3,'Data Entry'!$C$5:$C$34,0), _xlfn.XMATCH(BU10,'Data Entry'!$D$4:$Q$4,0))} -> 4745 | BX10: =BU10 -> Nov-26 | BY10: {=INDEX('Data Entry'!$D$5:$Q$34, _xlfn.XMATCH($V$24,'Data Entry'!$C$5:$C$34,0), _xlfn.XMATCH(BX10,'Data Entry'!$D$4:$Q$4,0))} -> 38900 | CB10: =BX10 -> Nov-26 | CC10: {=INDEX('Data Entry'!$D$5:$Q$34, _xlfn.XMATCH($V$34,'Data Entry'!$C$5:$C$34,0), _xlfn.XMATCH(CB10,'Data Entry'!$D$4:$Q$4,0))} -> 207700 | CF10: Selected Month Value: | CG10: =_xlfn.XLOOKUP($N$5,$CB$4:$CB$17,$CC$4:$CC$17,"") -> 255432
BB11: X - Bookmarks | BJ11: {=IFERROR(INDEX(_xlfn.ANCHORARRAY($BB$3),ROWS($BF$2:BF10)),"")} -> X - Bookmarks | BK11: =IF(BJ11="","",TRIM(_xlfn.TEXTAFTER(BJ11,"-"))) -> Bookmarks | BL11: {=IF(BJ11="","",INDEX('Data Entry'!$D$5:$Q$34,_xlfn.XMATCH(BJ11,'Data Entry'!$C$5:$C$34,0),_xlfn.XMATCH($N$5,'Data Entry'!$D$4:$Q$4,0)))} -> 527 | BM11: =IF(BL11="","", IF(ISNUMBER(SEARCH("Engagement rate",BK11)), TEXT(BL11,"0.0%"), TEXT(BL11,"#,##0"))) -> 527 | BN11: {=IF(BJ11="","",INDEX('Data Entry'!$AA$5:$AN$34,_xlfn.XMATCH(BJ11,'Data Entry'!$Z$5:$Z$34,0),_xlfn.XMATCH($N$5,'Data Entry'!$AA$4:$AN$4,0)))} -> 0.18161435 | BO11: =IF(BN11="","",IF(BN11>0,"▲ "&TEXT(BN11,"0.00%"),IF(BN11<0,"▼ "&TEXT(ABS(BN11),"0.00%"),"▬ 0.00%"))) -> ▲ 18.16% | BU11: =MensData[[#Headers],[Dec-26]] -> Dec-26 | BV11: {=INDEX('Data Entry'!$D$5:$Q$34, _xlfn.XMATCH($BS$3,'Data Entry'!$C$5:$C$34,0), _xlfn.XMATCH(BU11,'Data Entry'!$D$4:$Q$4,0))} -> 5639 | BX11: =BU11 -> Dec-26 | BY11: {=INDEX('Data Entry'!$D$5:$Q$34, _xlfn.XMATCH($V$24,'Data Entry'!$C$5:$C$34,0), _xlfn.XMATCH(BX11,'Data Entry'!$D$4:$Q$4,0))} -> 33900 | CB11: =BX11 -> Dec-26 | CC11: {=INDEX('Data Entry'!$D$5:$Q$34, _xlfn.XMATCH($V$34,'Data Entry'!$C$5:$C$34,0), _xlfn.XMATCH(CB11,'Data Entry'!$D$4:$Q$4,0))} -> 255432 | CF11: Performance vs Avg: | CG11: =(CG10-CG8)/CG8 -> -0.41360324 | CH11: =IF((CG10-CG8)/CG8>0, "▲ "&TEXT((CG10-CG8)/CG8,"0.0%"), IF((CG10-CG8)/CG8<0, "▼ "&TEXT(ABS((CG10-CG8)/CG8),"0.0%"), "– 0.0%")) -> ▼ 41.4%
BB12: X - Shares | BJ12: {=IFERROR(INDEX(_xlfn.ANCHORARRAY($BB$3),ROWS($BF$2:BF11)),"")} -> X - Shares | BK12: =IF(BJ12="","",TRIM(_xlfn.TEXTAFTER(BJ12,"-"))) -> Shares | BL12: {=IF(BJ12="","",INDEX('Data Entry'!$D$5:$Q$34,_xlfn.XMATCH(BJ12,'Data Entry'!$C$5:$C$34,0),_xlfn.XMATCH($N$5,'Data Entry'!$D$4:$Q$4,0)))} -> 576 | BM12: =IF(BL12="","", IF(ISNUMBER(SEARCH("Engagement rate",BK12)), TEXT(BL12,"0.0%"), TEXT(BL12,"#,##0"))) -> 576 | BN12: {=IF(BJ12="","",INDEX('Data Entry'!$AA$5:$AN$34,_xlfn.XMATCH(BJ12,'Data Entry'!$Z$5:$Z$34,0),_xlfn.XMATCH($N$5,'Data Entry'!$AA$4:$AN$4,0)))} -> 0.0034843206 | BO12: =IF(BN12="","",IF(BN12>0,"▲ "&TEXT(BN12,"0.00%"),IF(BN12<0,"▼ "&TEXT(ABS(BN12),"0.00%"),"▬ 0.00%"))) -> ▲ 0.35% | BU12: =MensData[[#Headers],[Jan-27]] -> Jan-27 | BV12: {=INDEX('Data Entry'!$D$5:$Q$34, _xlfn.XMATCH($BS$3,'Data Entry'!$C$5:$C$34,0), _xlfn.XMATCH(BU12,'Data Entry'!$D$4:$Q$4,0))} -> 16500 | BX12: =BU12 -> Jan-27 | BY12: {=INDEX('Data Entry'!$D$5:$Q$34, _xlfn.XMATCH($V$24,'Data Entry'!$C$5:$C$34,0), _xlfn.XMATCH(BX12,'Data Entry'!$D$4:$Q$4,0))} -> 69040 | CB12: =BX12 -> Jan-27 | CC12: {=INDEX('Data Entry'!$D$5:$Q$34, _xlfn.XMATCH($V$34,'Data Entry'!$C$5:$C$34,0), _xlfn.XMATCH(CB12,'Data Entry'!$D$4:$Q$4,0))} -> 464100
BB13: X - Video Views | BJ13: {=IFERROR(INDEX(_xlfn.ANCHORARRAY($BB$3),ROWS($BF$2:BF12)),"")} -> X - Video Views | BK13: =IF(BJ13="","",TRIM(_xlfn.TEXTAFTER(BJ13,"-"))) -> Video Views | BL13: {=IF(BJ13="","",INDEX('Data Entry'!$D$5:$Q$34,_xlfn.XMATCH(BJ13,'Data Entry'!$C$5:$C$34,0),_xlfn.XMATCH($N$5,'Data Entry'!$D$4:$Q$4,0)))} -> 255432 | BM13: =IF(BL13="","", IF(ISNUMBER(SEARCH("Engagement rate",BK13)), TEXT(BL13,"0.0%"), TEXT(BL13,"#,##0"))) -> 255,432 | BN13: {=IF(BJ13="","",INDEX('Data Entry'!$AA$5:$AN$34,_xlfn.XMATCH(BJ13,'Data Entry'!$Z$5:$Z$34,0),_xlfn.XMATCH($N$5,'Data Entry'!$AA$4:$AN$4,0)))} -> 0.22981223 | BO13: =IF(BN13="","",IF(BN13>0,"▲ "&TEXT(BN13,"0.00%"),IF(BN13<0,"▼ "&TEXT(ABS(BN13),"0.00%"),"▬ 0.00%"))) -> ▲ 22.98% | BU13: =MensData[[#Headers],[Feb-27]] -> Feb-27 | BV13: {=INDEX('Data Entry'!$D$5:$Q$34, _xlfn.XMATCH($BS$3,'Data Entry'!$C$5:$C$34,0), _xlfn.XMATCH(BU13,'Data Entry'!$D$4:$Q$4,0))} -> 4354 | BX13: =BU13 -> Feb-27 | BY13: {=INDEX('Data Entry'!$D$5:$Q$34, _xlfn.XMATCH($V$24,'Data Entry'!$C$5:$C$34,0), _xlfn.XMATCH(BX13,'Data Entry'!$D$4:$Q$4,0))} -> 70123 | CB13: =BX13 -> Feb-27 | CC13: {=INDEX('Data Entry'!$D$5:$Q$34, _xlfn.XMATCH($V$34,'Data Entry'!$C$5:$C$34,0), _xlfn.XMATCH(CB13,'Data Entry'!$D$4:$Q$4,0))} -> 450000
BJ14: {=IFERROR(INDEX(_xlfn.ANCHORARRAY($BB$3),ROWS($BF$2:BF13)),"")} | BK14: =IF(BJ14="","",TRIM(_xlfn.TEXTAFTER(BJ14,"-"))) | BL14: {=IF(BJ14="","",INDEX('Data Entry'!$D$5:$Q$34,_xlfn.XMATCH(BJ14,'Data Entry'!$C$5:$C$34,0),_xlfn.XMATCH($N$5,'Data Entry'!$D$4:$Q$4,0)))} | BM14: =IF(BL14="","", IF(ISNUMBER(SEARCH("Engagement rate",BK14)), TEXT(BL14,"0.0%"), TEXT(BL14,"#,##0"))) | BN14: {=IF(BJ14="","",INDEX('Data Entry'!$AA$5:$AN$34,_xlfn.XMATCH(BJ14,'Data Entry'!$Z$5:$Z$34,0),_xlfn.XMATCH($N$5,'Data Entry'!$AA$4:$AN$4,0)))} | BO14: =IF(BN14="","",IF(BN14>0,"▲ "&TEXT(BN14,"0.00%"),IF(BN14<0,"▼ "&TEXT(ABS(BN14),"0.00%"),"▬ 0.00%"))) | BU14: =MensData[[#Headers],[Mar-27]] -> Mar-27 | BV14: {=INDEX('Data Entry'!$D$5:$Q$34, _xlfn.XMATCH($BS$3,'Data Entry'!$C$5:$C$34,0), _xlfn.XMATCH(BU14,'Data Entry'!$D$4:$Q$4,0))} -> 3243 | BX14: =BU14 -> Mar-27 | BY14: {=INDEX('Data Entry'!$D$5:$Q$34, _xlfn.XMATCH($V$24,'Data Entry'!$C$5:$C$34,0), _xlfn.XMATCH(BX14,'Data Entry'!$D$4:$Q$4,0))} -> 67888 | CB14: =BX14 -> Mar-27 | CC14: {=INDEX('Data Entry'!$D$5:$Q$34, _xlfn.XMATCH($V$34,'Data Entry'!$C$5:$C$34,0), _xlfn.XMATCH(CB14,'Data Entry'!$D$4:$Q$4,0))} -> 465789
BJ15: {=IFERROR(INDEX(_xlfn.ANCHORARRAY($BB$3),ROWS($BF$2:BF14)),"")} | BK15: =IF(BJ15="","",TRIM(_xlfn.TEXTAFTER(BJ15,"-"))) | BL15: {=IF(BJ15="","",INDEX('Data Entry'!$D$5:$Q$34,_xlfn.XMATCH(BJ15,'Data Entry'!$C$5:$C$34,0),_xlfn.XMATCH($N$5,'Data Entry'!$D$4:$Q$4,0)))} | BM15: =IF(BL15="","", IF(ISNUMBER(SEARCH("Engagement rate",BK15)), TEXT(BL15,"0.0%"), TEXT(BL15,"#,##0"))) | BN15: {=IF(BJ15="","",INDEX('Data Entry'!$AA$5:$AN$34,_xlfn.XMATCH(BJ15,'Data Entry'!$Z$5:$Z$34,0),_xlfn.XMATCH($N$5,'Data Entry'!$AA$4:$AN$4,0)))} | BO15: =IF(BN15="","",IF(BN15>0,"▲ "&TEXT(BN15,"0.00%"),IF(BN15<0,"▼ "&TEXT(ABS(BN15),"0.00%"),"▬ 0.00%"))) | BU15: =MensData[[#Headers],[Apr-27]] -> Apr-27 | BV15: {=INDEX('Data Entry'!$D$5:$Q$34, _xlfn.XMATCH($BS$3,'Data Entry'!$C$5:$C$34,0), _xlfn.XMATCH(BU15,'Data Entry'!$D$4:$Q$4,0))} -> 3453 | BX15: =BU15 -> Apr-27 | BY15: {=INDEX('Data Entry'!$D$5:$Q$34, _xlfn.XMATCH($V$24,'Data Entry'!$C$5:$C$34,0), _xlfn.XMATCH(BX15,'Data Entry'!$D$4:$Q$4,0))} -> 65768 | CB15: =BX15 -> Apr-27 | CC15: {=INDEX('Data Entry'!$D$5:$Q$34, _xlfn.XMATCH($V$34,'Data Entry'!$C$5:$C$34,0), _xlfn.XMATCH(CB15,'Data Entry'!$D$4:$Q$4,0))} -> 657000
BU16: =MensData[[#Headers],[May-27]] -> May-27 | BV16: {=INDEX('Data Entry'!$D$5:$Q$34, _xlfn.XMATCH($BS$3,'Data Entry'!$C$5:$C$34,0), _xlfn.XMATCH(BU16,'Data Entry'!$D$4:$Q$4,0))} -> 5555 | BX16: =BU16 -> May-27 | BY16: {=INDEX('Data Entry'!$D$5:$Q$34, _xlfn.XMATCH($V$24,'Data Entry'!$C$5:$C$34,0), _xlfn.XMATCH(BX16,'Data Entry'!$D$4:$Q$4,0))} -> 64555 | CB16: =BX16 -> May-27 | CC16: {=INDEX('Data Entry'!$D$5:$Q$34, _xlfn.XMATCH($V$34,'Data Entry'!$C$5:$C$34,0), _xlfn.XMATCH(CB16,'Data Entry'!$D$4:$Q$4,0))} -> 451232
BU17: =MensData[[#Headers],[Jun-27]] -> Jun-27 | BV17: {=INDEX('Data Entry'!$D$5:$Q$34, _xlfn.XMATCH($BS$3,'Data Entry'!$C$5:$C$34,0), _xlfn.XMATCH(BU17,'Data Entry'!$D$4:$Q$4,0))} -> 4365 | BX17: =BU17 -> Jun-27 | BY17: {=INDEX('Data Entry'!$D$5:$Q$34, _xlfn.XMATCH($V$24,'Data Entry'!$C$5:$C$34,0), _xlfn.XMATCH(BX17,'Data Entry'!$D$4:$Q$4,0))} -> 55432 | CB17: =BX17 -> Jun-27 | CC17: {=INDEX('Data Entry'!$D$5:$Q$34, _xlfn.XMATCH($V$34,'Data Entry'!$C$5:$C$34,0), _xlfn.XMATCH(CB17,'Data Entry'!$D$4:$Q$4,0))} -> 442789
CL22: Metric | CM22: Card Title | CN22: Value | CO22: Growth | CP22: Growth Display
C23: Platform ▼ | U23: Platform ▼ | V23: Metric ▼ | BX23: {=_xlfn.LET( _xlpm.p,_xlfn.SWITCH($U$24, "X","X -", "TikTok","TT -", "Instagram","IG -", "Threads","THREADS -", "Facebook","FB -", "LinkedIn","LINKEDIN -", ""), _xlfn._xlws.FILTER( 'Data Entry'!$C$5:$C$100, LEFT('Data Entry'!$C$5:$C$100,LEN(_xlpm.p))=_xlpm.p, "" ))} -> X - Followers | BZ23: =U24&" - "&TRIM(_xlfn.TEXTAFTER(V24,"-")) -> X - Profile visits | CB23: {=_xlfn.LET( _xlpm.p,_xlfn.SWITCH($U$34, "X","X -", "TikTok","TT -", "Instagram","IG -", "Threads","THREADS -", "Facebook","FB -", "LinkedIn","LINKEDIN -", ""), _xlfn._xlws.FILTER( 'Data Entry'!$C$5:$C$100, LEFT('Data Entry'!$C$5:$C$100,LEN(_xlpm.p))=_xlpm.p, "" ))} -> X - Followers | CJ23: {=_xlfn.LET( _xlpm.p,_xlfn.SWITCH($C$34, "X","X -", "TikTok","TT -", "Instagram","IG -", "Threads","THREADS -", "Facebook","FB -", "LinkedIn","LINKEDIN -", ""), _xlfn._xlws.FILTER( 'Data Entry'!$C$5:$C$100, LEFT('Data Entry'!$C$5:$C$100,LEN(_xlpm.p))=_xlpm.p, "" ))} -> TT - Views | CL23: {=IFERROR(INDEX(_xlfn.ANCHORARRAY($CJ$23),ROWS($CL$23:CL23)),"")} -> TT - Views | CM23: =IF(CL23="","",TRIM(_xlfn.TEXTAFTER(CL23,"-"))) -> Views | CN23: {=IF(CL23="","",INDEX('Data Entry'!$D$5:$Q$34,_xlfn.XMATCH(CL23,'Data Entry'!$C$5:$C$34,0),_xlfn.XMATCH($N$5,'Data Entry'!$D$4:$Q$4,0)))} -> 486000 | CO23: {=IF(CL23="","",INDEX('Data Entry'!$AA$5:$AN$34,_xlfn.XMATCH(CL23,'Data Entry'!$Z$5:$Z$34,0),_xlfn.XMATCH($N$5,'Data Entry'!$AA$4:$AN$4,0)))} -> 1.0165975 | CP23: =IF(CO23="","",IF(CO23>0,"▲ "&TEXT(CO23,"0.00%"),IF(CO23<0,"▼ "&TEXT(ABS(CO23),"0.00%"),"▬ 0.00%"))) -> ▲ 101.66%
C24: Threads | U24: X | V24: X - Profile visits | BX24: X - Impressions | CB24: X - Impressions | CJ24: TT - Profile Views | CL24: {=IFERROR(INDEX(_xlfn.ANCHORARRAY($CJ$23),ROWS($CL$23:CL24)),"")} -> TT - Profile Views | CM24: =IF(CL24="","",TRIM(_xlfn.TEXTAFTER(CL24,"-"))) -> Profile Views | CN24: {=IF(CL24="","",INDEX('Data Entry'!$D$5:$Q$34,_xlfn.XMATCH(CL24,'Data Entry'!$C$5:$C$34,0),_xlfn.XMATCH($N$5,'Data Entry'!$D$4:$Q$4,0)))} -> 7800 | CO24: {=IF(CL24="","",INDEX('Data Entry'!$AA$5:$AN$34,_xlfn.XMATCH(CL24,'Data Entry'!$Z$5:$Z$34,0),_xlfn.XMATCH($N$5,'Data Entry'!$AA$4:$AN$4,0)))} -> 0.25806452 | CP24: =IF(CO24="","",IF(CO24>0,"▲ "&TEXT(CO24,"0.00%"),IF(CO24<0,"▼ "&TEXT(ABS(CO24),"0.00%"),"▬ 0.00%"))) -> ▲ 25.81%
BX25: X - Engagement rate | CB25: X - Engagement rate | CJ25: TT - Likes | CL25: {=IFERROR(INDEX(_xlfn.ANCHORARRAY($CJ$23),ROWS($CL$23:CL25)),"")} -> TT - Likes | CM25: =IF(CL25="","",TRIM(_xlfn.TEXTAFTER(CL25,"-"))) -> Likes | CN25: {=IF(CL25="","",INDEX('Data Entry'!$D$5:$Q$34,_xlfn.XMATCH(CL25,'Data Entry'!$C$5:$C$34,0),_xlfn.XMATCH($N$5,'Data Entry'!$D$4:$Q$4,0)))} -> 35000 | CO25: {=IF(CL25="","",INDEX('Data Entry'!$AA$5:$AN$34,_xlfn.XMATCH(CL25,'Data Entry'!$Z$5:$Z$34,0),_xlfn.XMATCH($N$5,'Data Entry'!$AA$4:$AN$4,0)))} -> 0.75 | CP25: =IF(CO25="","",IF(CO25>0,"▲ "&TEXT(CO25,"0.00%"),IF(CO25<0,"▼ "&TEXT(ABS(CO25),"0.00%"),"▬ 0.00%"))) -> ▲ 75.00%
BX26: X - Engagements | CB26: X - Engagements | CJ26: TT - Comments | CL26: {=IFERROR(INDEX(_xlfn.ANCHORARRAY($CJ$23),ROWS($CL$23:CL26)),"")} -> TT - Comments | CM26: =IF(CL26="","",TRIM(_xlfn.TEXTAFTER(CL26,"-"))) -> Comments | CN26: {=IF(CL26="","",INDEX('Data Entry'!$D$5:$Q$34,_xlfn.XMATCH(CL26,'Data Entry'!$C$5:$C$34,0),_xlfn.XMATCH($N$5,'Data Entry'!$D$4:$Q$4,0)))} -> 378 | CO26: {=IF(CL26="","",INDEX('Data Entry'!$AA$5:$AN$34,_xlfn.XMATCH(CL26,'Data Entry'!$Z$5:$Z$34,0),_xlfn.XMATCH($N$5,'Data Entry'!$AA$4:$AN$4,0)))} -> 0.13513514 | CP26: =IF(CO26="","",IF(CO26>0,"▲ "&TEXT(CO26,"0.00%"),IF(CO26<0,"▼ "&TEXT(ABS(CO26),"0.00%"),"▬ 0.00%"))) -> ▲ 13.51%
BX27: X - Profile visits | CB27: X - Profile visits | CJ27: TT - Shares | CL27: {=IFERROR(INDEX(_xlfn.ANCHORARRAY($CJ$23),ROWS($CL$23:CL27)),"")} -> TT - Shares | CM27: =IF(CL27="","",TRIM(_xlfn.TEXTAFTER(CL27,"-"))) -> Shares | CN27: {=IF(CL27="","",INDEX('Data Entry'!$D$5:$Q$34,_xlfn.XMATCH(CL27,'Data Entry'!$C$5:$C$34,0),_xlfn.XMATCH($N$5,'Data Entry'!$D$4:$Q$4,0)))} -> 882 | CO27: {=IF(CL27="","",INDEX('Data Entry'!$AA$5:$AN$34,_xlfn.XMATCH(CL27,'Data Entry'!$Z$5:$Z$34,0),_xlfn.XMATCH($N$5,'Data Entry'!$AA$4:$AN$4,0)))} -> 0.24576271 | CP27: =IF(CO27="","",IF(CO27>0,"▲ "&TEXT(CO27,"0.00%"),IF(CO27<0,"▼ "&TEXT(ABS(CO27),"0.00%"),"▬ 0.00%"))) -> ▲ 24.58%
BX28: X - Replies | CB28: X - Replies | CJ28: TT - New Viewers | CL28: {=IFERROR(INDEX(_xlfn.ANCHORARRAY($CJ$23),ROWS($CL$23:CL28)),"")} -> TT - New Viewers | CM28: =IF(CL28="","",TRIM(_xlfn.TEXTAFTER(CL28,"-"))) -> New Viewers | CN28: {=IF(CL28="","",INDEX('Data Entry'!$D$5:$Q$34,_xlfn.XMATCH(CL28,'Data Entry'!$C$5:$C$34,0),_xlfn.XMATCH($N$5,'Data Entry'!$D$4:$Q$4,0)))} -> 184000 | CO28: {=IF(CL28="","",INDEX('Data Entry'!$AA$5:$AN$34,_xlfn.XMATCH(CL28,'Data Entry'!$Z$5:$Z$34,0),_xlfn.XMATCH($N$5,'Data Entry'!$AA$4:$AN$4,0)))} -> 3.3809524 | CP28: =IF(CO28="","",IF(CO28>0,"▲ "&TEXT(CO28,"0.00%"),IF(CO28<0,"▼ "&TEXT(ABS(CO28),"0.00%"),"▬ 0.00%"))) -> ▲ 338.10%
BX29: X - Likes | CB29: X - Likes | CL29: {=IFERROR(INDEX(_xlfn.ANCHORARRAY($CJ$23),ROWS($CL$23:CL29)),"")} | CM29: =IF(CL29="","",TRIM(_xlfn.TEXTAFTER(CL29,"-"))) | CN29: {=IF(CL29="","",INDEX('Data Entry'!$D$5:$Q$34,_xlfn.XMATCH(CL29,'Data Entry'!$C$5:$C$34,0),_xlfn.XMATCH($N$5,'Data Entry'!$D$4:$Q$4,0)))} | CO29: {=IF(CL29="","",INDEX('Data Entry'!$AA$5:$AN$34,_xlfn.XMATCH(CL29,'Data Entry'!$Z$5:$Z$34,0),_xlfn.XMATCH($N$5,'Data Entry'!$AA$4:$AN$4,0)))} | CP29: =IF(CO29="","",IF(CO29>0,"▲ "&TEXT(CO29,"0.00%"),IF(CO29<0,"▼ "&TEXT(ABS(CO29),"0.00%"),"▬ 0.00%")))
BX30: X - Reposts | CB30: X - Reposts | CL30: {=IFERROR(INDEX(_xlfn.ANCHORARRAY($CJ$23),ROWS($CL$23:CL30)),"")} | CM30: =IF(CL30="","",TRIM(_xlfn.TEXTAFTER(CL30,"-"))) | CN30: {=IF(CL30="","",INDEX('Data Entry'!$D$5:$Q$34,_xlfn.XMATCH(CL30,'Data Entry'!$C$5:$C$34,0),_xlfn.XMATCH($N$5,'Data Entry'!$D$4:$Q$4,0)))} | CO30: {=IF(CL30="","",INDEX('Data Entry'!$AA$5:$AN$34,_xlfn.XMATCH(CL30,'Data Entry'!$Z$5:$Z$34,0),_xlfn.XMATCH($N$5,'Data Entry'!$AA$4:$AN$4,0)))} | CP30: =IF(CO30="","",IF(CO30>0,"▲ "&TEXT(CO30,"0.00%"),IF(CO30<0,"▼ "&TEXT(ABS(CO30),"0.00%"),"▬ 0.00%")))
BX31: X - Bookmarks | CB31: X - Bookmarks | CL31: {=IFERROR(INDEX(_xlfn.ANCHORARRAY($CJ$23),ROWS($CL$23:CL31)),"")} | CM31: =IF(CL31="","",TRIM(_xlfn.TEXTAFTER(CL31,"-"))) | CN31: {=IF(CL31="","",INDEX('Data Entry'!$D$5:$Q$34,_xlfn.XMATCH(CL31,'Data Entry'!$C$5:$C$34,0),_xlfn.XMATCH($N$5,'Data Entry'!$D$4:$Q$4,0)))} | CO31: {=IF(CL31="","",INDEX('Data Entry'!$AA$5:$AN$34,_xlfn.XMATCH(CL31,'Data Entry'!$Z$5:$Z$34,0),_xlfn.XMATCH($N$5,'Data Entry'!$AA$4:$AN$4,0)))} | CP31: =IF(CO31="","",IF(CO31>0,"▲ "&TEXT(CO31,"0.00%"),IF(CO31<0,"▼ "&TEXT(ABS(CO31),"0.00%"),"▬ 0.00%")))
BX32: X - Shares | CB32: X - Shares | CL32: {=IFERROR(INDEX(_xlfn.ANCHORARRAY($CJ$23),ROWS($CL$23:CL32)),"")} | CM32: =IF(CL32="","",TRIM(_xlfn.TEXTAFTER(CL32,"-"))) | CN32: {=IF(CL32="","",INDEX('Data Entry'!$D$5:$Q$34,_xlfn.XMATCH(CL32,'Data Entry'!$C$5:$C$34,0),_xlfn.XMATCH($N$5,'Data Entry'!$D$4:$Q$4,0)))} | CO32: {=IF(CL32="","",INDEX('Data Entry'!$AA$5:$AN$34,_xlfn.XMATCH(CL32,'Data Entry'!$Z$5:$Z$34,0),_xlfn.XMATCH($N$5,'Data Entry'!$AA$4:$AN$4,0)))} | CP32: =IF(CO32="","",IF(CO32>0,"▲ "&TEXT(CO32,"0.00%"),IF(CO32<0,"▼ "&TEXT(ABS(CO32),"0.00%"),"▬ 0.00%")))
C33: Platform ▼ | U33: Platform ▼ | V33: Metric ▼ | BX33: X - Video Views | CB33: X - Video Views | CL33: {=IFERROR(INDEX(_xlfn.ANCHORARRAY($CJ$23),ROWS($CL$23:CL33)),"")} | CM33: =IF(CL33="","",TRIM(_xlfn.TEXTAFTER(CL33,"-"))) | CN33: {=IF(CL33="","",INDEX('Data Entry'!$D$5:$Q$34,_xlfn.XMATCH(CL33,'Data Entry'!$C$5:$C$34,0),_xlfn.XMATCH($N$5,'Data Entry'!$D$4:$Q$4,0)))} | CO33: {=IF(CL33="","",INDEX('Data Entry'!$AA$5:$AN$34,_xlfn.XMATCH(CL33,'Data Entry'!$Z$5:$Z$34,0),_xlfn.XMATCH($N$5,'Data Entry'!$AA$4:$AN$4,0)))} | CP33: =IF(CO33="","",IF(CO33>0,"▲ "&TEXT(CO33,"0.00%"),IF(CO33<0,"▼ "&TEXT(ABS(CO33),"0.00%"),"▬ 0.00%")))
C34: TikTok | U34: X | V34: X - Video Views | CL34: {=IFERROR(INDEX(_xlfn.ANCHORARRAY($CJ$23),ROWS($CL$23:CL34)),"")} | CM34: =IF(CL34="","",TRIM(_xlfn.TEXTAFTER(CL34,"-"))) | CN34: {=IF(CL34="","",INDEX('Data Entry'!$D$5:$Q$34,_xlfn.XMATCH(CL34,'Data Entry'!$C$5:$C$34,0),_xlfn.XMATCH($N$5,'Data Entry'!$D$4:$Q$4,0)))} | CO34: {=IF(CL34="","",INDEX('Data Entry'!$AA$5:$AN$34,_xlfn.XMATCH(CL34,'Data Entry'!$Z$5:$Z$34,0),_xlfn.XMATCH($N$5,'Data Entry'!$AA$4:$AN$4,0)))} | CP34: =IF(CO34="","",IF(CO34>0,"▲ "&TEXT(CO34,"0.00%"),IF(CO34<0,"▼ "&TEXT(ABS(CO34),"0.00%"),"▬ 0.00%")))
CL35: {=IFERROR(INDEX(_xlfn.ANCHORARRAY($CJ$23),ROWS($CL$23:CL35)),"")} | CM35: =IF(CL35="","",TRIM(_xlfn.TEXTAFTER(CL35,"-"))) | CN35: {=IF(CL35="","",INDEX('Data Entry'!$D$5:$Q$34,_xlfn.XMATCH(CL35,'Data Entry'!$C$5:$C$34,0),_xlfn.XMATCH($N$5,'Data Entry'!$D$4:$Q$4,0)))} | CO35: {=IF(CL35="","",INDEX('Data Entry'!$AA$5:$AN$34,_xlfn.XMATCH(CL35,'Data Entry'!$Z$5:$Z$34,0),_xlfn.XMATCH($N$5,'Data Entry'!$AA$4:$AN$4,0)))} | CP35: =IF(CO35="","",IF(CO35>0,"▲ "&TEXT(CO35,"0.00%"),IF(CO35<0,"▼ "&TEXT(ABS(CO35),"0.00%"),"▬ 0.00%")))
CL36: {=IFERROR(INDEX(_xlfn.ANCHORARRAY($CJ$23),ROWS($CL$23:CL36)),"")} | CM36: =IF(CL36="","",TRIM(_xlfn.TEXTAFTER(CL36,"-"))) | CN36: {=IF(CL36="","",INDEX('Data Entry'!$D$5:$Q$34,_xlfn.XMATCH(CL36,'Data Entry'!$C$5:$C$34,0),_xlfn.XMATCH($N$5,'Data Entry'!$D$4:$Q$4,0)))} | CO36: {=IF(CL36="","",INDEX('Data Entry'!$AA$5:$AN$34,_xlfn.XMATCH(CL36,'Data Entry'!$Z$5:$Z$34,0),_xlfn.XMATCH($N$5,'Data Entry'!$AA$4:$AN$4,0)))} | CP36: =IF(CO36="","",IF(CO36>0,"▲ "&TEXT(CO36,"0.00%"),IF(CO36<0,"▼ "&TEXT(ABS(CO36),"0.00%"),"▬ 0.00%")))
CL37: {=IFERROR(INDEX(_xlfn.ANCHORARRAY($CJ$23),ROWS($CL$23:CL37)),"")} | CM37: =IF(CL37="","",TRIM(_xlfn.TEXTAFTER(CL37,"-"))) | CN37: {=IF(CL37="","",INDEX('Data Entry'!$D$5:$Q$34,_xlfn.XMATCH(CL37,'Data Entry'!$C$5:$C$34,0),_xlfn.XMATCH($N$5,'Data Entry'!$D$4:$Q$4,0)))} | CO37: {=IF(CL37="","",INDEX('Data Entry'!$AA$5:$AN$34,_xlfn.XMATCH(CL37,'Data Entry'!$Z$5:$Z$34,0),_xlfn.XMATCH($N$5,'Data Entry'!$AA$4:$AN$4,0)))} | CP37: =IF(CO37="","",IF(CO37>0,"▲ "&TEXT(CO37,"0.00%"),IF(CO37<0,"▼ "&TEXT(ABS(CO37),"0.00%"),"▬ 0.00%")))
CL38: {=IFERROR(INDEX(_xlfn.ANCHORARRAY($CJ$23),ROWS($CL$23:CL38)),"")} | CM38: =IF(CL38="","",TRIM(_xlfn.TEXTAFTER(CL38,"-"))) | CN38: {=IF(CL38="","",INDEX('Data Entry'!$D$5:$Q$34,_xlfn.XMATCH(CL38,'Data Entry'!$C$5:$C$34,0),_xlfn.XMATCH($N$5,'Data Entry'!$D$4:$Q$4,0)))} | CO38: {=IF(CL38="","",INDEX('Data Entry'!$AA$5:$AN$34,_xlfn.XMATCH(CL38,'Data Entry'!$Z$5:$Z$34,0),_xlfn.XMATCH($N$5,'Data Entry'!$AA$4:$AN$4,0)))} | CP38: =IF(CO38="","",IF(CO38>0,"▲ "&TEXT(CO38,"0.00%"),IF(CO38<0,"▼ "&TEXT(ABS(CO38),"0.00%"),"▬ 0.00%")))
CL39: {=IFERROR(INDEX(_xlfn.ANCHORARRAY($CJ$23),ROWS($CL$23:CL39)),"")} | CM39: =IF(CL39="","",TRIM(_xlfn.TEXTAFTER(CL39,"-"))) | CN39: {=IF(CL39="","",INDEX('Data Entry'!$D$5:$Q$34,_xlfn.XMATCH(CL39,'Data Entry'!$C$5:$C$34,0),_xlfn.XMATCH($N$5,'Data Entry'!$D$4:$Q$4,0)))} | CO39: {=IF(CL39="","",INDEX('Data Entry'!$AA$5:$AN$34,_xlfn.XMATCH(CL39,'Data Entry'!$Z$5:$Z$34,0),_xlfn.XMATCH($N$5,'Data Entry'!$AA$4:$AN$4,0)))} | CP39: =IF(CO39="","",IF(CO39>0,"▲ "&TEXT(CO39,"0.00%"),IF(CO39<0,"▼ "&TEXT(ABS(CO39),"0.00%"),"▬ 0.00%")))

Sheet Data Entry
A1: MENS | G1: NOTE: LEAVE cells that haven't got a value e.g., next months as 0, NOT BLANK - this is to avoid errors and also create better charts
X2: Percentage difference tables
A3: Raw Data Table
C4: Metric | D4: May-26 | E4: Jun-26 | F4: Jul-26 | G4: Aug-26 | H4: Sep-26 | I4: Oct-26 | J4: Nov-26 | K4: Dec-26 | L4: Jan-27 | M4: Feb-27 | N4: Mar-27 | O4: Apr-27 | P4: May-27 | Q4: Jun-27 | Z4: Metric | AA4: May-26 | AB4: Jun-26 | AC4: Jul-26 | AD4: Aug-26 | AE4: Sep-26 | AF4: Oct-26 | AG4: Nov-26 | AH4: Dec-26 | AI4: Jan-27 | AJ4: Feb-27 | AK4: Mar-27 | AL4: Apr-27 | AM4: May-27 | AN4: Jun-27
C5: X - Followers | D5: 232000 | E5: 233000 | F5: 233423 | G5: 236781 | H5: 240543 | I5: 238000 | J5: 241300 | K5: 242000 | L5: 242222 | M5: 245654 | N5: 246578 | O5: 247600 | P5: 247800 | Q5: 246546 | Z5: X - Followers | AB5: =(MensData[[#This Row],[Jun-26]]-MensData[[#This Row],[May-26]])/MensData[[#This Row],[May-26]] -> 0.0043103448 | AC5: =(MensData[[#This Row],[Jul-26]]-MensData[[#This Row],[Jun-26]])/MensData[[#This Row],[Jun-26]] -> 0.0018154506 | AD5: =(MensData[[#This Row],[Aug-26]]-MensData[[#This Row],[Jul-26]])/MensData[[#This Row],[Jul-26]] -> 0.0143859 | AE5: =(MensData[[#This Row],[Sep-26]]-MensData[[#This Row],[Aug-26]])/MensData[[#This Row],[Aug-26]] -> 0.015888099 | AF5: =(MensData[[#This Row],[Oct-26]]-MensData[[#This Row],[Sep-26]])/MensData[[#This Row],[Sep-26]] -> -0.010571914 | AG5: =(MensData[[#This Row],[Nov-26]]-MensData[[#This Row],[Oct-26]])/MensData[[#This Row],[Oct-26]] -> 0.013865546 | AH5: =(MensData[[#This Row],[Dec-26]]-MensData[[#This Row],[Nov-26]])/MensData[[#This Row],[Nov-26]] -> 0.0029009532 | AI5: =(MensData[[#This Row],[Jan-27]]-MensData[[#This Row],[Dec-26]])/MensData[[#This Row],[Dec-26]] -> 0.00091735537 | AJ5: =(MensData[[#This Row],[Feb-27]]-MensData[[#This Row],[Jan-27]])/MensData[[#This Row],[Jan-27]] -> 0.01416882 | AK5: =(MensData[[#This Row],[Mar-27]]-MensData[[#This Row],[Feb-27]])/MensData[[#This Row],[Feb-27]] -> 0.003761388 | AL5: =(MensData[[#This Row],[Apr-27]]-MensData[[#This Row],[Mar-27]])/MensData[[#This Row],[Mar-27]] -> 0.0041447331 | AM5: =(MensData[[#This Row],[May-27]]-MensData[[#This Row],[Apr-27]])/MensData[[#This Row],[Apr-27]] -> 0.00080775444 | AN5: =(MensData[[#This Row],[Jun-27]]-MensData[[#This Row],[May-27]])/MensData[[#This Row],[May-27]] -> -0.0050605327
C6: X - Impressions | D6: 4366000 | E6: 6200000 | F6: 9400000 | G6: 9000000 | H6: 7500000 | I6: 3700000 | J6: 4400000 | K6: 3900000 | L6: 6543210 | M6: 4580000 | N6: 4356701 | O6: 5670002 | P6: 5458970 | Q6: 4325671 | Z6: X - Impressions | AB6: =(MensData[[#This Row],[Jun-26]]-MensData[[#This Row],[May-26]])/MensData[[#This Row],[May-26]] -> 0.42006413 | AC6: =(MensData[[#This Row],[Jul-26]]-MensData[[#This Row],[Jun-26]])/MensData[[#This Row],[Jun-26]] -> 0.51612903 | AD6: =(MensData[[#This Row],[Aug-26]]-MensData[[#This Row],[Jul-26]])/MensData[[#This Row],[Jul-26]] -> -0.042553191 | AE6: =(MensData[[#This Row],[Sep-26]]-MensData[[#This Row],[Aug-26]])/MensData[[#This Row],[Aug-26]] -> -0.16666667 | AF6: =(MensData[[#This Row],[Oct-26]]-MensData[[#This Row],[Sep-26]])/MensData[[#This Row],[Sep-26]] -> -0.50666667 | AG6: =(MensData[[#This Row],[Nov-26]]-MensData[[#This Row],[Oct-26]])/MensData[[#This Row],[Oct-26]] -> 0.18918919 | AH6: =(MensData[[#This Row],[Dec-26]]-MensData[[#This Row],[Nov-26]])/MensData[[#This Row],[Nov-26]] -> -0.11363636 | AI6: =(MensData[[#This Row],[Jan-27]]-MensData[[#This Row],[Dec-26]])/MensData[[#This Row],[Dec-26]] -> 0.67774615 | AJ6: =(MensData[[#This Row],[Feb-27]]-MensData[[#This Row],[Jan-27]])/MensData[[#This Row],[Jan-27]] -> -0.30003775 | AK6: =(MensData[[#This Row],[Mar-27]]-MensData[[#This Row],[Feb-27]])/MensData[[#This Row],[Feb-27]] -> -0.04875524 | AL6: =(MensData[[#This Row],[Apr-27]]-MensData[[#This Row],[Mar-27]])/MensData[[#This Row],[Mar-27]] -> 0.30144391 | AM6: =(MensData[[#This Row],[May-27]]-MensData[[#This Row],[Apr-27]])/MensData[[#This Row],[Apr-27]] -> -0.037219034 | AN6: =(MensData[[#This Row],[Jun-27]]-MensData[[#This Row],[May-27]])/MensData[[#This Row],[May-27]] -> -0.20760308
C7: X - Engagement rate | D7: 0.024 | E7: 0.043 | F7: 0.044 | G7: 0.041 | H7: 0.041 | I7: 0.038 | J7: 0.042 | K7: 0.046 | L7: 0.039 | M7: 0.027 | N7: 0.0333 | O7: 0.0453 | P7: 0.0432 | Q7: 0.0345 | Z7: X - Engagement rate | AB7: =(MensData[[#This Row],[Jun-26]]-MensData[[#This Row],[May-26]])/MensData[[#This Row],[May-26]] -> 0.79166667 | AC7: =(MensData[[#This Row],[Jul-26]]-MensData[[#This Row],[Jun-26]])/MensData[[#This Row],[Jun-26]] -> 0.023255814 | AD7: =(MensData[[#This Row],[Aug-26]]-MensData[[#This Row],[Jul-26]])/MensData[[#This Row],[Jul-26]] -> -0.068181818 | AE7: =(MensData[[#This Row],[Sep-26]]-MensData[[#This Row],[Aug-26]])/MensData[[#This Row],[Aug-26]] -> 0 | AF7: =(MensData[[#This Row],[Oct-26]]-MensData[[#This Row],[Sep-26]])/MensData[[#This Row],[Sep-26]] -> -0.073170732 | AG7: =(MensData[[#This Row],[Nov-26]]-MensData[[#This Row],[Oct-26]])/MensData[[#This Row],[Oct-26]] -> 0.10526316 | AH7: =(MensData[[#This Row],[Dec-26]]-MensData[[#This Row],[Nov-26]])/MensData[[#This Row],[Nov-26]] -> 0.095238095 | AI7: =(MensData[[#This Row],[Jan-27]]-MensData[[#This Row],[Dec-26]])/MensData[[#This Row],[Dec-26]] -> -0.15217391 | AJ7: =(MensData[[#This Row],[Feb-27]]-MensData[[#This Row],[Jan-27]])/MensData[[#This Row],[Jan-27]] -> -0.30769231 | AK7: =(MensData[[#This Row],[Mar-27]]-MensData[[#This Row],[Feb-27]])/MensData[[#This Row],[Feb-27]] -> 0.23333333 | AL7: =(MensData[[#This Row],[Apr-27]]-MensData[[#This Row],[Mar-27]])/MensData[[#This Row],[Mar-27]] -> 0.36036036 | AM7: =(MensData[[#This Row],[May-27]]-MensData[[#This Row],[Apr-27]])/MensData[[#This Row],[Apr-27]] -> -0.046357616 | AN7: =(MensData[[#This Row],[Jun-27]]-MensData[[#This Row],[May-27]])/MensData[[#This Row],[May-27]] -> -0.20138889
C8: X - Engagements | D8: 136000 | E8: 357000 | F8: 422500 | G8: 377700 | H8: 313000 | I8: 134000 | J8: 189700 | K8: 183400 | L8: 386154 | M8: 432111 | N8: 422111 | O8: 234555 | P8: 324123 | Q8: 326122 | Z8: X - Engagements | AB8: =(MensData[[#This Row],[Jun-26]]-MensData[[#This Row],[May-26]])/MensData[[#This Row],[May-26]] -> 1.625 | AC8: =(MensData[[#This Row],[Jul-26]]-MensData[[#This Row],[Jun-26]])/MensData[[#This Row],[Jun-26]] -> 0.18347339 | AD8: =(MensData[[#This Row],[Aug-26]]-MensData[[#This Row],[Jul-26]])/MensData[[#This Row],[Jul-26]] -> -0.1060355 | AE8: =(MensData[[#This Row],[Sep-26]]-MensData[[#This Row],[Aug-26]])/MensData[[#This Row],[Aug-26]] -> -0.17129997 | AF8: =(MensData[[#This Row],[Oct-26]]-MensData[[#This Row],[Sep-26]])/MensData[[#This Row],[Sep-26]] -> -0.57188498 | AG8: =(MensData[[#This Row],[Nov-26]]-MensData[[#This Row],[Oct-26]])/MensData[[#This Row],[Oct-26]] -> 0.41567164 | AH8: =(MensData[[#This Row],[Dec-26]]-MensData[[#This Row],[Nov-26]])/MensData[[#This Row],[Nov-26]] -> -0.033210332 | AI8: =(MensData[[#This Row],[Jan-27]]-MensData[[#This Row],[Dec-26]])/MensData[[#This Row],[Dec-26]] -> 1.1055289 | AJ8: =(MensData[[#This Row],[Feb-27]]-MensData[[#This Row],[Jan-27]])/MensData[[#This Row],[Jan-27]] -> 0.1190121 | AK8: =(MensData[[#This Row],[Mar-27]]-MensData[[#This Row],[Feb-27]])/MensData[[#This Row],[Feb-27]] -> -0.023142202 | AL8: =(MensData[[#This Row],[Apr-27]]-MensData[[#This Row],[Mar-27]])/MensData[[#This Row],[Mar-27]] -> -0.44432862 | AM8: =(MensData[[#This Row],[May-27]]-MensData[[#This Row],[Apr-27]])/MensData[[#This Row],[Apr-27]] -> 0.38186353 | AN8: =(MensData[[#This Row],[Jun-27]]-MensData[[#This Row],[May-27]])/MensData[[#This Row],[May-27]] -> 0.0061674118
C9: X - Profile visits | D9: 29800 | E9: 89200 | F9: 100600 | G9: 71900 | H9: 68100 | I9: 34300 | J9: 38900 | K9: 33900 | L9: 69040 | M9: 70123 | N9: 67888 | O9: 65768 | P9: 64555 | Q9: 55432 | Z9: X - Profile visits | AB9: =(MensData[[#This Row],[Jun-26]]-MensData[[#This Row],[May-26]])/MensData[[#This Row],[May-26]] -> 1.9932886 | AC9: =(MensData[[#This Row],[Jul-26]]-MensData[[#This Row],[Jun-26]])/MensData[[#This Row],[Jun-26]] -> 0.12780269 | AD9: =(MensData[[#This Row],[Aug-26]]-MensData[[#This Row],[Jul-26]])/MensData[[#This Row],[Jul-26]] -> -0.28528827 | AE9: =(MensData[[#This Row],[Sep-26]]-MensData[[#This Row],[Aug-26]])/MensData[[#This Row],[Aug-26]] -> -0.052851182 | AF9: =(MensData[[#This Row],[Oct-26]]-MensData[[#This Row],[Sep-26]])/MensData[[#This Row],[Sep-26]] -> -0.49632893 | AG9: =(MensData[[#This Row],[Nov-26]]-MensData[[#This Row],[Oct-26]])/MensData[[#This Row],[Oct-26]] -> 0.13411079 | AH9: =(MensData[[#This Row],[Dec-26]]-MensData[[#This Row],[Nov-26]])/MensData[[#This Row],[Nov-26]] -> -0.1285347 | AI9: =(MensData[[#This Row],[Jan-27]]-MensData[[#This Row],[Dec-26]])/MensData[[#This Row],[Dec-26]] -> 1.0365782 | AJ9: =(MensData[[#This Row],[Feb-27]]-MensData[[#This Row],[Jan-27]])/MensData[[#This Row],[Jan-27]] -> 0.015686559 | AK9: =(MensData[[#This Row],[Mar-27]]-MensData[[#This Row],[Feb-27]])/MensData[[#This Row],[Feb-27]] -> -0.031872567 | AL9: =(MensData[[#This Row],[Apr-27]]-MensData[[#This Row],[Mar-27]])/MensData[[#This Row],[Mar-27]] -> -0.031227905 | AM9: =(MensData[[#This Row],[May-27]]-MensData[[#This Row],[Apr-27]])/MensData[[#This Row],[Apr-27]] -> -0.01844362 | AN9: =(MensData[[#This Row],[Jun-27]]-MensData[[#This Row],[May-27]])/MensData[[#This Row],[May-27]] -> -0.14132135
C10: X - Replies | D10: 1340 | E10: 2400 | F10: 3300 | G10: 3900 | H10: 4700 | I10: 3800 | J10: 3200 | K10: 3900 | L10: 6400 | M10: 7544 | N10: 7200 | O10: 6500 | P10: 5600 | Q10: 7234 | Z10: X - Replies | AB10: =(MensData[[#This Row],[Jun-26]]-MensData[[#This Row],[May-26]])/MensData[[#This Row],[May-26]] -> 0.79104478 | AC10: =(MensData[[#This Row],[Jul-26]]-MensData[[#This Row],[Jun-26]])/MensData[[#This Row],[Jun-26]] -> 0.375 | AD10: =(MensData[[#This Row],[Aug-26]]-MensData[[#This Row],[Jul-26]])/MensData[[#This Row],[Jul-26]] -> 0.18181818 | AE10: =(MensData[[#This Row],[Sep-26]]-MensData[[#This Row],[Aug-26]])/MensData[[#This Row],[Aug-26]] -> 0.20512821 | AF10: =(MensData[[#This Row],[Oct-26]]-MensData[[#This Row],[Sep-26]])/MensData[[#This Row],[Sep-26]] -> -0.19148936 | AG10: =(MensData[[#This Row],[Nov-26]]-MensData[[#This Row],[Oct-26]])/MensData[[#This Row],[Oct-26]] -> -0.15789474 | AH10: =(MensData[[#This Row],[Dec-26]]-MensData[[#This Row],[Nov-26]])/MensData[[#This Row],[Nov-26]] -> 0.21875 | AI10: =(MensData[[#This Row],[Jan-27]]-MensData[[#This Row],[Dec-26]])/MensData[[#This Row],[Dec-26]] -> 0.64102564 | AJ10: =(MensData[[#This Row],[Feb-27]]-MensData[[#This Row],[Jan-27]])/MensData[[#This Row],[Jan-27]] -> 0.17875 | AK10: =(MensData[[#This Row],[Mar-27]]-MensData[[#This Row],[Feb-27]])/MensData[[#This Row],[Feb-27]] -> -0.045599152 | AL10: =(MensData[[#This Row],[Apr-27]]-MensData[[#This Row],[Mar-27]])/MensData[[#This Row],[Mar-27]] -> -0.097222222 | AM10: =(MensData[[#This Row],[May-27]]-MensData[[#This Row],[Apr-27]])/MensData[[#This Row],[Apr-27]] -> -0.13846154 | AN10: =(MensData[[#This Row],[Jun-27]]-MensData[[#This Row],[May-27]])/MensData[[#This Row],[May-27]] -> 0.29178571
C11: X - Likes | D11: 14270 | E11: 27400 | F11: 52300 | G11: 57600 | H11: 37600 | I11: 10800 | J11: 22500 | K11: 26300 | L11: 49065 | M11: 51890 | N11: 43444 | O11: 47089 | P11: 51234 | Q11: 32000 | Z11: X - Likes | AB11: =(MensData[[#This Row],[Jun-26]]-MensData[[#This Row],[May-26]])/MensData[[#This Row],[May-26]] -> 0.92011212 | AC11: =(MensData[[#This Row],[Jul-26]]-MensData[[#This Row],[Jun-26]])/MensData[[#This Row],[Jun-26]] -> 0.90875912 | AD11: =(MensData[[#This Row],[Aug-26]]-MensData[[#This Row],[Jul-26]])/MensData[[#This Row],[Jul-26]] -> 0.10133843 | AE11: =(MensData[[#This Row],[Sep-26]]-MensData[[#This Row],[Aug-26]])/MensData[[#This Row],[Aug-26]] -> -0.34722222 | AF11: =(MensData[[#This Row],[Oct-26]]-MensData[[#This Row],[Sep-26]])/MensData[[#This Row],[Sep-26]] -> -0.71276596 | AG11: =(MensData[[#This Row],[Nov-26]]-MensData[[#This Row],[Oct-26]])/MensData[[#This Row],[Oct-26]] -> 1.0833333 | AH11: =(MensData[[#This Row],[Dec-26]]-MensData[[#This Row],[Nov-26]])/MensData[[#This Row],[Nov-26]] -> 0.16888889 | AI11: =(MensData[[#This Row],[Jan-27]]-MensData[[#This Row],[Dec-26]])/MensData[[#This Row],[Dec-26]] -> 0.86558935 | AJ11: =(MensData[[#This Row],[Feb-27]]-MensData[[#This Row],[Jan-27]])/MensData[[#This Row],[Jan-27]] -> 0.057576684 | AK11: =(MensData[[#This Row],[Mar-27]]-MensData[[#This Row],[Feb-27]])/MensData[[#This Row],[Feb-27]] -> -0.16276739 | AL11: =(MensData[[#This Row],[Apr-27]]-MensData[[#This Row],[Mar-27]])/MensData[[#This Row],[Mar-27]] -> 0.083901114 | AM11: =(MensData[[#This Row],[May-27]]-MensData[[#This Row],[Apr-27]])/MensData[[#This Row],[Apr-27]] -> 0.088024804 | AN11: =(MensData[[#This Row],[Jun-27]]-MensData[[#This Row],[May-27]])/MensData[[#This Row],[May-27]] -> -0.37541476
C12: X - Reposts | D12: 899 | E12: 1700 | F12: 2300 | G12: 3100 | H12: 2400 | I12: 992 | J12: 1400 | K12: 1300 | L12: 3466 | M12: 2456 | N12: 1234 | O12: 4321 | P12: 2341 | Q12: 3421 | Z12: X - Reposts | AB12: =(MensData[[#This Row],[Jun-26]]-MensData[[#This Row],[May-26]])/MensData[[#This Row],[May-26]] -> 0.89098999 | AC12: =(MensData[[#This Row],[Jul-26]]-MensData[[#This Row],[Jun-26]])/MensData[[#This Row],[Jun-26]] -> 0.35294118 | AD12: =(MensData[[#This Row],[Aug-26]]-MensData[[#This Row],[Jul-26]])/MensData[[#This Row],[Jul-26]] -> 0.34782609 | AE12: =(MensData[[#This Row],[Sep-26]]-MensData[[#This Row],[Aug-26]])/MensData[[#This Row],[Aug-26]] -> -0.22580645 | AF12: =(MensData[[#This Row],[Oct-26]]-MensData[[#This Row],[Sep-26]])/MensData[[#This Row],[Sep-26]] -> -0.58666667 | AG12: =(MensData[[#This Row],[Nov-26]]-MensData[[#This Row],[Oct-26]])/MensData[[#This Row],[Oct-26]] -> 0.41129032 | AH12: =(MensData[[#This Row],[Dec-26]]-MensData[[#This Row],[Nov-26]])/MensData[[#This Row],[Nov-26]] -> -0.071428571 | AI12: =(MensData[[#This Row],[Jan-27]]-MensData[[#This Row],[Dec-26]])/MensData[[#This Row],[Dec-26]] -> 1.6661538 | AJ12: =(MensData[[#This Row],[Feb-27]]-MensData[[#This Row],[Jan-27]])/MensData[[#This Row],[Jan-27]] -> -0.29140219 | AK12: =(MensData[[#This Row],[Mar-27]]-MensData[[#This Row],[Feb-27]])/MensData[[#This Row],[Feb-27]] -> -0.497557 | AL12: =(MensData[[#This Row],[Apr-27]]-MensData[[#This Row],[Mar-27]])/MensData[[#This Row],[Mar-27]] -> 2.5016207 | AM12: =(MensData[[#This Row],[May-27]]-MensData[[#This Row],[Apr-27]])/MensData[[#This Row],[Apr-27]] -> -0.45822726 | AN12: =(MensData[[#This Row],[Jun-27]]-MensData[[#This Row],[May-27]])/MensData[[#This Row],[May-27]] -> 0.46134131
C13: X - Bookmarks | D13: 456 | E13: 817 | F13: 1100 | G13: 859 | H13: 731 | I13: 394 | J13: 446 | K13: 527 | L13: 1240 | M13: 980 | N13: 970 | O13: 567 | P13: 657 | Q13: 598 | Z13: X - Bookmarks | AB13: =(MensData[[#This Row],[Jun-26]]-MensData[[#This Row],[May-26]])/MensData[[#This Row],[May-26]] -> 0.79166667 | AC13: =(MensData[[#This Row],[Jul-26]]-MensData[[#This Row],[Jun-26]])/MensData[[#This Row],[Jun-26]] -> 0.34638923 | AD13: =(MensData[[#This Row],[Aug-26]]-MensData[[#This Row],[Jul-26]])/MensData[[#This Row],[Jul-26]] -> -0.21909091 | AE13: =(MensData[[#This Row],[Sep-26]]-MensData[[#This Row],[Aug-26]])/MensData[[#This Row],[Aug-26]] -> -0.14901048 | AF13: =(MensData[[#This Row],[Oct-26]]-MensData[[#This Row],[Sep-26]])/MensData[[#This Row],[Sep-26]] -> -0.46101231 | AG13: =(MensData[[#This Row],[Nov-26]]-MensData[[#This Row],[Oct-26]])/MensData[[#This Row],[Oct-26]] -> 0.1319797 | AH13: =(MensData[[#This Row],[Dec-26]]-MensData[[#This Row],[Nov-26]])/MensData[[#This Row],[Nov-26]] -> 0.18161435 | AI13: =(MensData[[#This Row],[Jan-27]]-MensData[[#This Row],[Dec-26]])/MensData[[#This Row],[Dec-26]] -> 1.3529412 | AJ13: =(MensData[[#This Row],[Feb-27]]-MensData[[#This Row],[Jan-27]])/MensData[[#This Row],[Jan-27]] -> -0.20967742 | AK13: =(MensData[[#This Row],[Mar-27]]-MensData[[#This Row],[Feb-27]])/MensData[[#This Row],[Feb-27]] -> -0.010204082 | AL13: =(MensData[[#This Row],[Apr-27]]-MensData[[#This Row],[Mar-27]])/MensData[[#This Row],[Mar-27]] -> -0.41546392 | AM13: =(MensData[[#This Row],[May-27]]-MensData[[#This Row],[Apr-27]])/MensData[[#This Row],[Apr-27]] -> 0.15873016 | AN13: =(MensData[[#This Row],[Jun-27]]-MensData[[#This Row],[May-27]])/MensData[[#This Row],[May-27]] -> -0.089802131
C14: X - Shares | D14: 1034 | E14: 1800 | F14: 1900 | G14: 1300 | H14: 1200 | I14: 548 | J14: 574 | K14: 576 | L14: 2242 | M14: 768 | N14: 1022 | O14: 456 | P14: 678 | Q14: 777 | Z14: X - Shares | AB14: =(MensData[[#This Row],[Jun-26]]-MensData[[#This Row],[May-26]])/MensData[[#This Row],[May-26]] -> 0.74081238 | AC14: =(MensData[[#This Row],[Jul-26]]-MensData[[#This Row],[Jun-26]])/MensData[[#This Row],[Jun-26]] -> 0.055555556 | AD14: =(MensData[[#This Row],[Aug-26]]-MensData[[#This Row],[Jul-26]])/MensData[[#This Row],[Jul-26]] -> -0.31578947 | AE14: =(MensData[[#This Row],[Sep-26]]-MensData[[#This Row],[Aug-26]])/MensData[[#This Row],[Aug-26]] -> -0.076923077 | AF14: =(MensData[[#This Row],[Oct-26]]-MensData[[#This Row],[Sep-26]])/MensData[[#This Row],[Sep-26]] -> -0.54333333 | AG14: =(MensData[[#This Row],[Nov-26]]-MensData[[#This Row],[Oct-26]])/MensData[[#This Row],[Oct-26]] -> 0.047445255 | AH14: =(MensData[[#This Row],[Dec-26]]-MensData[[#This Row],[Nov-26]])/MensData[[#This Row],[Nov-26]] -> 0.0034843206 | AI14: =(MensData[[#This Row],[Jan-27]]-MensData[[#This Row],[Dec-26]])/MensData[[#This Row],[Dec-26]] -> 2.8923611 | AJ14: =(MensData[[#This Row],[Feb-27]]-MensData[[#This Row],[Jan-27]])/MensData[[#This Row],[Jan-27]] -> -0.65744871 | AK14: =(MensData[[#This Row],[Mar-27]]-MensData[[#This Row],[Feb-27]])/MensData[[#This Row],[Feb-27]] -> 0.33072917 | AL14: =(MensData[[#This Row],[Apr-27]]-MensData[[#This Row],[Mar-27]])/MensData[[#This Row],[Mar-27]] -> -0.55381605 | AM14: =(MensData[[#This Row],[May-27]]-MensData[[#This Row],[Apr-27]])/MensData[[#This Row],[Apr-27]] -> 0.48684211 | AN14: =(MensData[[#This Row],[Jun-27]]-MensData[[#This Row],[May-27]])/MensData[[#This Row],[May-27]] -> 0.1460177
C15: X - Video Views | D15: 342600 | E15: 493400 | F15: 698800 | G15: 613900 | H15: 322100 | I15: 233500 | J15: 207700 | K15: 255432 | L15: 464100 | M15: 450000 | N15: 465789 | O15: 657000 | P15: 451232 | Q15: 442789 | Z15: X - Video Views | AB15: =(MensData[[#This Row],[Jun-26]]-MensData[[#This Row],[May-26]])/MensData[[#This Row],[May-26]] -> 0.44016346 | AC15: =(MensData[[#This Row],[Jul-26]]-MensData[[#This Row],[Jun-26]])/MensData[[#This Row],[Jun-26]] -> 0.4162951 | AD15: =(MensData[[#This Row],[Aug-26]]-MensData[[#This Row],[Jul-26]])/MensData[[#This Row],[Jul-26]] -> -0.12149399 | AE15: =(MensData[[#This Row],[Sep-26]]-MensData[[#This Row],[Aug-26]])/MensData[[#This Row],[Aug-26]] -> -0.47532171 | AF15: =(MensData[[#This Row],[Oct-26]]-MensData[[#This Row],[Sep-26]])/MensData[[#This Row],[Sep-26]] -> -0.27506985 | AG15: =(MensData[[#This Row],[Nov-26]]-MensData[[#This Row],[Oct-26]])/MensData[[#This Row],[Oct-26]] -> -0.11049251 | AH15: =(MensData[[#This Row],[Dec-26]]-MensData[[#This Row],[Nov-26]])/MensData[[#This Row],[Nov-26]] -> 0.22981223 | AI15: =(MensData[[#This Row],[Jan-27]]-MensData[[#This Row],[Dec-26]])/MensData[[#This Row],[Dec-26]] -> 0.81692192 | AJ15: =(MensData[[#This Row],[Feb-27]]-MensData[[#This Row],[Jan-27]])/MensData[[#This Row],[Jan-27]] -> -0.030381383 | AK15: =(MensData[[#This Row],[Mar-27]]-MensData[[#This Row],[Feb-27]])/MensData[[#This Row],[Feb-27]] -> 0.035086667 | AL15: =(MensData[[#This Row],[Apr-27]]-MensData[[#This Row],[Mar-27]])/MensData[[#This Row],[Mar-27]] -> 0.41050991 | AM15: =(MensData[[#This Row],[May-27]]-MensData[[#This Row],[Apr-27]])/MensData[[#This Row],[Apr-27]] -> -0.3131933 | AN15: =(MensData[[#This Row],[Jun-27]]-MensData[[#This Row],[May-27]])/MensData[[#This Row],[May-27]] -> -0.018710996
C16: TT - Views | D16: 800000 | E16: 1000000 | F16: 1400000 | G16: 454000 | H16: 237000 | I16: 48000 | J16: 241000 | K16: 486000 | L16: 689000 | M16: 700100 | N16: 771222 | O16: 675688 | P16: 564355 | Q16: 546788 | Z16: TT - Views | AB16: =(MensData[[#This Row],[Jun-26]]-MensData[[#This Row],[May-26]])/MensData[[#This Row],[May-26]] -> 0.25 | AC16: =(MensData[[#This Row],[Jul-26]]-MensData[[#This Row],[Jun-26]])/MensData[[#This Row],[Jun-26]] -> 0.4 | AD16: =(MensData[[#This Row],[Aug-26]]-MensData[[#This Row],[Jul-26]])/MensData[[#This Row],[Jul-26]] -> -0.67571429 | AE16: =(MensData[[#This Row],[Sep-26]]-MensData[[#This Row],[Aug-26]])/MensData[[#This Row],[Aug-26]] -> -0.47797357 | AF16: =(MensData[[#This Row],[Oct-26]]-MensData[[#This Row],[Sep-26]])/MensData[[#This Row],[Sep-26]] -> -0.79746835 | AG16: =(MensData[[#This Row],[Nov-26]]-MensData[[#This Row],[Oct-26]])/MensData[[#This Row],[Oct-26]] -> 4.0208333 | AH16: =(MensData[[#This Row],[Dec-26]]-MensData[[#This Row],[Nov-26]])/MensData[[#This Row],[Nov-26]] -> 1.0165975 | AI16: =(MensData[[#This Row],[Jan-27]]-MensData[[#This Row],[Dec-26]])/MensData[[#This Row],[Dec-26]] -> 0.41769547 | AJ16: =(MensData[[#This Row],[Feb-27]]-MensData[[#This Row],[Jan-27]])/MensData[[#This Row],[Jan-27]] -> 0.016110305 | AK16: =(MensData[[#This Row],[Mar-27]]-MensData[[#This Row],[Feb-27]])/MensData[[#This Row],[Feb-27]] -> 0.10158834 | AL16: =(MensData[[#This Row],[Apr-27]]-MensData[[#This Row],[Mar-27]])/MensData[[#This Row],[Mar-27]] -> -0.12387354 | AM16: =(MensData[[#This Row],[May-27]]-MensData[[#This Row],[Apr-27]])/MensData[[#This Row],[Apr-27]] -> -0.16476983 | AN16: =(MensData[[#This Row],[Jun-27]]-MensData[[#This Row],[May-27]])/MensData[[#This Row],[May-27]] -> -0.03112757
... C34: LINKEDIN - Comments | D34: 43 | E34: 23 | F34: 35 | G34: 42 | H34: 37 | I34: 82 | J34: 56 | K34: 73 | L34: 66 | M34: 32 | N34: 45 | O34: 64 | P34: 48 | Q34: 52 | Z34: LINKEDIN - Comments | AB34: =(MensData[[#This Row],[Jun-26]]-MensData[[#This Row],[May-26]])/MensData[[#This Row],[May-26]] -> -0.46511628 | AC34: =(MensData[[#This Row],[Jul-26]]-MensData[[#This Row],[Jun-26]])/MensData[[#This Row],[Jun-26]] -> 0.52173913 | AD34: =(MensData[[#This Row],[Aug-26]]-MensData[[#This Row],[Jul-26]])/MensData[[#This Row],[Jul-26]] -> 0.2 | AE34: =(MensData[[#This Row],[Sep-26]]-MensData[[#This Row],[Aug-26]])/MensData[[#This Row],[Aug-26]] -> -0.11904762 | AF34: =(MensData[[#This Row],[Oct-26]]-MensData[[#This Row],[Sep-26]])/MensData[[#This Row],[Sep-26]] -> 1.2162162 | AG34: =(MensData[[#This Row],[Nov-26]]-MensData[[#This Row],[Oct-26]])/MensData[[#This Row],[Oct-26]] -> -0.31707317 | AH34: =(MensData[[#This Row],[Dec-26]]-MensData[[#This Row],[Nov-26]])/MensData[[#This Row],[Nov-26]] -> 0.30357143 | AI34: =(MensData[[#This Row],[Jan-27]]-MensData[[#This Row],[Dec-26]])/MensData[[#This Row],[Dec-26]] -> -0.095890411 | AJ34: =(MensData[[#This Row],[Feb-27]]-MensData[[#This Row],[Jan-27]])/MensData[[#This Row],[Jan-27]] -> -0.51515152 | AK34: =(MensData[[#This Row],[Mar-27]]-MensData[[#This Row],[Feb-27]])/MensData[[#This Row],[Feb-27]] -> 0.40625 | AL34: =(MensData[[#This Row],[Apr-27]]-MensData[[#This Row],[Mar-27]])/MensData[[#This Row],[Mar-27]] -> 0.42222222 | AM34: =(MensData[[#This Row],[May-27]]-MensData[[#This Row],[Apr-27]])/MensData[[#This Row],[Apr-27]] -> -0.25 | AN34: =(MensData[[#This Row],[Jun-27]]-MensData[[#This Row],[May-27]])/MensData[[#This Row],[May-27]] -> 0.083333333

Sheet Processed Data
A1: ='Data Entry'!E4 -> Jun-26 | I1: ='Data Entry'!F4 -> Jul-26 | P1: ='Data Entry'!G4 -> Aug-26 | X1: ='Data Entry'!H4 -> Sep-26 | AF1: ='Data Entry'!I4 -> Oct-26 | AN1: ='Data Entry'!J4 -> Nov-26 | AV1: ='Data Entry'!K4 -> Dec-26 | BE1: ='Data Entry'!L4 -> Jan-27 | BM1: ='Data Entry'!M4 -> Feb-27 | BT1: ='Data Entry'!N4 -> Mar-27 | CB1: ='Data Entry'!O4 -> Apr-27 | CJ1: ='Data Entry'!P4 -> May-27 | CR1: ='Data Entry'!Q4 -> Jun-27
A3: X | B3: Metric | C3: Amount | D3: Monthly Change | I3: X | J3: Metric | K3: Amount | L3: Monthly Change | P3: X | Q3: Metric | R3: Amount | S3: Monthly Change | X3: X | Y3: Metric | Z3: Amount | AA3: Monthly Change | AF3: X | AG3: Metric | AH3: Amount | AI3: Monthly Change | AN3: X | AO3: Metric | AP3: Amount | AQ3: Monthly Change | AV3: X | AW3: Metric | AX3: Amount | AY3: Monthly Change | BE3: X | BF3: Metric | BG3: Amount | BH3: Monthly Change | BM3: X | BN3: Metric | BO3: Amount | BP3: Monthly Change | BT3: X | BU3: Metric | BV3: Amount | BW3: Monthly Change | CB3: X | CC3: Metric | CD3: Amount | CE3: Monthly Change | CJ3: X | CK3: Metric | CL3: Amount | CM3: Monthly Change | CR3: X | CS3: Metric | CT3: Amount | CU3: Monthly Change
B4: Followers | C4: ='Data Entry'!E5 -> 233000 | D4: ='Data Entry'!AB5 -> 0.0043103448 | J4: Followers | K4: ='Data Entry'!F5 -> 233423 | L4: ='Data Entry'!AC5 -> 0.0018154506 | Q4: Followers | R4: ='Data Entry'!G5 -> 236781 | S4: ='Data Entry'!AD5 -> 0.0143859 | Y4: Followers | Z4: ='Data Entry'!H5 -> 240543 | AA4: ='Data Entry'!AE5 -> 0.015888099 | AG4: Followers | AH4: ='Data Entry'!I5 -> 238000 | AI4: ='Data Entry'!AF5 -> -0.010571914 | AO4: Followers | AP4: ='Data Entry'!J5 -> 241300 | AQ4: ='Data Entry'!AG5 -> 0.013865546 | AW4: Followers | AX4: ='Data Entry'!K5 -> 242000 | AY4: ='Data Entry'!AH5 -> 0.0029009532 | BF4: Followers | BG4: ='Data Entry'!L5 -> 242222 | BH4: ='Data Entry'!AI5 -> 0.00091735537 | BN4: Followers | BO4: ='Data Entry'!M5 -> 245654 | BP4: ='Data Entry'!AJ5 -> 0.01416882 | BU4: Followers | BV4: ='Data Entry'!N5 -> 246578 | BW4: ='Data Entry'!AK5 -> 0.003761388 | CC4: Followers | CD4: ='Data Entry'!O5 -> 247600 | CE4: ='Data Entry'!AL5 -> 0.0041447331 | CK4: Followers | CL4: ='Data Entry'!P5 -> 247800 | CM4: ='Data Entry'!AM5 -> 0.00080775444 | CS4: Followers | CT4: ='Data Entry'!Q5 -> 246546 | CU4: ='Data Entry'!AN5 -> -0.0050605327
